Workbook

Sheet README
A1: কীভাবে পূরণ করবেন (How to fill)
A2: ১. কোন কলামে লিখবেন | B2: শুধু আপনার নিজের উপভাষার কলামে লিখবেন (সবুজ হেডার)। অন্য কোনো কলামে হাত দেবেন না।
A3: ২. অনুবাদ নয়, স্বাভাবিক কথা | B3: ‘standard_query’ বাক্যটি শব্দে শব্দে অনুবাদ করবেন না। বাড়িতে বড়দের সঙ্গে যেভাবে বলেন, সেভাবে লিখুন। বাক্যের গঠন বদলাতে পারেন, কিন্তু প্রশ্নের অর্থ, জায়গার নাম, সংখ্যা ও আইডি বদলাবেন না।
A4: ৩. লেখার হরফ | B4: বাংলা কীবোর্ডে বাংলা হরফে লিখুন (ইংরেজি হরফে বাংলা বা Banglish নয়)।
A5: ৪. বানান | B5: কথা যেমন শোনায় তেমন লিখুন। আদর্শ বানানে জোর করে ফেরাবেন না। বানানে কিছুটা তফাত হলে সমস্যা নেই।
A6: ৫. Status কলাম | B6: Claude-এর draft দেওয়া থাকলে: ঠিক থাকলে 'native_verified', ভুল থাকলে নিজে ঠিক করে 'native_corrected'। ঘর ফাঁকা থাকলে নিজে লিখে 'native_written'।
A7: ৬. যেগুলো পারবেন না | B7: সেগুলো ফাঁকা রাখুন। জোর করে অনুমান করবেন না।
A8: ৭. কোন ক্রমে করবেন | B8: উপরের সারি থেকে ক্রমানুসারে করুন (block 1, তারপর 2...)। প্রতি ৪০ সারির block-এ সব ধরনের প্রশ্ন সমানভাবে মেশানো আছে, তাই যতদূর পারবেন ততদূরই যথেষ্ট।
A10: Example row (এইভাবে)
A11: standard_query | B11: জ্বর হলে বাড়িতে কী করা উচিত?
A12: barishal (example) | B12: জ্বর হইলে বাড়িতে কী করন লাগে?
A13: status (example) | B13: native_verified
A15: Legend
A16: Yellow cell | B16: Claude-এর draft: অবশ্যই আপনার যাচাই লাগবে (native_verified / native_corrected)
A17: Green header | B17: আপনার পূরণের কলাম (dialect columns)
A18: Blue header | B18: নিজে বদলাবেন না (id, topic, type, labels)
A20: Note for researcher | B20: Draft only for Barishal, Rajshahi, Rangpur and only for block 1 (Q001-Q040); written by Claude, unverified until a native speaker marks it. Chittagong and Natore are left blank on purpose. Unverified drafts must be counted as synthetic, not native, in the paper. gold_passage_id is filled after the knowledge base is built.

Sheet Base_Queries
A1: id | B1: block | C1: topic | D1: type | E1: standard_query | F1: expected_behavior | G1: gold_tool | H1: gold_args | I1: gold_passage_id | J1: barishal | K1: chittagong | L1: rajshahi | M1: rangpur | N1: natore | O1: barishal_status | P1: chittagong_status | Q1: rajshahi_status | R1: rangpur_status | S1: natore_status
A2: Q001 | B2: 1 | C2: abohawa | D2: tool | E2: কাল চট্টগ্রামে বৃষ্টি হবে কি? | F2: call_tool | G2: get_weather_forecast | H2: {"location": "চট্টগ্রাম", "date": "আগামীকাল"} | J2: কাইল চট্টগ্রামে বৃষ্টি হইব নি? | L2: কাল চট্টগ্রামে বৃষ্টি হবেক কি? | M2: কাইল চট্টগ্রামত বৃষ্টি হইবে নি? | O2: claude_draft | Q2: claude_draft | R2: claude_draft
A3: Q002 | B3: 1 | C3: abohawa | D3: answerable | E3: অতিরিক্ত গরমে কৃষকরা কীভাবে নিজেকে সুস্থ রাখবেন? | F3: retrieve_and_answer | J3: বেশি গরমে কৃষকেরা কেমনে নিজেরে সুস্থ রাখব? | L3: বেশি গরমে চাষিরা কেমন করে নিজেকে সুস্থ রাখবে? | M3: বেশি গরমত চাষিরা কেমন করি নিজেক সুস্থ রাখিবে? | O3: claude_draft | Q3: claude_draft | R3: claude_draft
A4: Q003 | B4: 1 | C4: shorkari | D4: answerable | E4: জাতীয় পরিচয়পত্র হারিয়ে গেলে কী করতে হয়? | F4: retrieve_and_answer | J4: জাতীয় পরিচয়পত্র হারাইয়া গেলে কী করন লাগে? | L4: জাতীয় পরিচয়পত্র হারিয়ে গেলে কী করতে হয়? | M4: জাতীয় পরিচয়পত্র হারাইয়া গেইলে কী করিবার নাগে? | O4: claude_draft | Q4: claude_draft | R4: claude_draft
A5: Q004 | B5: 1 | C5: shorkari | D5: tool | E5: আমার জন্মনিবন্ধন আবেদনের নম্বর ৪৫২১৮৯, এখন অবস্থা কী? | F5: call_tool | G5: check_service_status | H5: {"service": "জন্মনিবন্ধন", "id": "452189"} | J5: আমার জন্মনিবন্ধন আবেদনের নম্বর ৪৫২১৮৯, অহন অবস্থা কী? | L5: আমার জন্মনিবন্ধন আবেদনের নম্বর ৪৫২১৮৯, এখুন অবস্থা কী? | M5: মোর জন্মনিবন্ধন আবেদনের নম্বর ৪৫২১৮৯, এলা অবস্থা কী? | O5: claude_draft | Q5: claude_draft | R5: claude_draft
A6: Q005 | B6: 1 | C6: abohawa | D6: unanswerable | E6: আগামী মাসে আমাদের গ্রামে ঠিক কোন দিন বৃষ্টি হবে? | F6: abstain | J6: সামনের মাসে আমাগো গ্রামে ঠিক কোন দিন বৃষ্টি হইব? | L6: সামনের মাসে মোদের গ্রামে ঠিক কোন দিন বৃষ্টি হবেক? | M6: সামনের মাসত মোর গাঁওত ঠিক কোন দিন বৃষ্টি হইবে? | O6: claude_draft | Q6: claude_draft | R6: claude_draft
A7: Q006 | B7: 1 | C7: shorkari | D7: unanswerable | E7: আমার জমির পর্চা কেউ জাল করেছে, মামলা কীভাবে করব? | F7: abstain | J7: আমার জমির পর্চা কেউ জাল করছে, মামলা কেমনে করমু? | L7: আমার জমির পর্চা কেউ জাল করেচে, মামলা কেমন করে করব? | M7: মোর জমির পর্চা কায়ো জাল করিচে, মামলা কেমন করি করিম? | O7: claude_draft | Q7: claude_draft | R7: claude_draft
A8: Q007 | B8: 1 | C8: swasthyo | D8: tool | E8: নাটোর সদর উপজেলায় গর্ভবতী মায়ের চেকআপ কোথায় করানো যায়? | F8: call_tool | G8: find_nearest_clinic | H8: {"upazila": "নাটোর সদর", "service": "গর্ভকালীন সেবা"} | J8: নাটোর সদর উপজেলায় পোয়াতি মায়ের চেকআপ কই করান যায়? | L8: নাটোর সদর উপজেলায় পোয়াতি মায়ের চেকআপ কুথায় করানো যায়? | M8: নাটোর সদর উপজেলাত পোয়াতি মায়ের চেকআপ কোটে করা যায়? | O8: claude_draft | Q8: claude_draft | R8: claude_draft
A9: Q008 | B9: 1 | C9: abohawa | D9: tool | E9: আজ রংপুরে তাপমাত্রা কত থাকবে? | F9: call_tool | G9: get_weather_forecast | H9: {"location": "রংপুর", "date": "আজ"} | J9: আইজ রংপুরে তাপমাত্রা কত থাকব? | L9: আজ রংপুরে তাপমাত্রা কত থাকবেক? | M9: আইজ রংপুরত তাপমাত্রা কত থাকিবে? | O9: claude_draft | Q9: claude_draft | R9: claude_draft
A10: Q009 | B10: 1 | C10: krishi | D10: answerable | E10: সবজির বীজ ভালোভাবে কীভাবে সংরক্ষণ করতে হয়? | F10: retrieve_and_answer | J10: সবজির বীজ ভালো কইরা কেমনে রাখন লাগে? | L10: সবজির বীজ ভালো করে কেমন করে রাখতে হয়? | M10: সবজির বীজ ভালো করি কেমন করি রাখবার নাগে? | O10: claude_draft | Q10: claude_draft | R10: claude_draft
A11: Q010 | B11: 1 | C11: swasthyo | D11: answerable | E11: ডায়রিয়া হলে খাবার স্যালাইন কীভাবে বানাতে হয়? | F11: retrieve_and_answer | J11: ডায়রিয়া হইলে খাওনের স্যালাইন কেমনে বানান লাগে? | L11: ডায়রিয়া হইলে খাবার স্যালাইন কেমন করে বানাতে হয়? | M11: ডায়রিয়া হইলে খাবার স্যালাইন কেমন করি বানাবার নাগে? | O11: claude_draft | Q11: claude_draft | R11: claude_draft
A12: Q011 | B12: 1 | C12: krishi | D12: tool | E12: রাজশাহীতে আলুর বাজারদর কেমন? | F12: call_tool | G12: get_crop_market_price | H12: {"crop": "আলু", "district": "রাজশাহী"} | J12: রাজশাহীতে আলুর বাজারদর কেমুন? | L12: রাজশাহীতে আলুর বাজারদর কেমুন? | M12: রাজশাহীত আলুর বাজারদর কেমন? | O12: claude_draft | Q12: claude_draft | R12: claude_draft
A13: Q012 | B13: 1 | C13: krishi | D13: unanswerable | E13: আগামী পাঁচ বছরে ধানের দাম কেমন হবে? | F13: abstain | J13: সামনে পাঁচ বছরে ধানের দাম কেমুন হইব? | L13: সামনে পাঁচ বছরে ধানের দাম কেমুন হবেক? | M13: আগামী পাঁচ বছরত ধানের দাম কেমন হইবে? | O13: claude_draft | Q13: claude_draft | R13: claude_draft
A14: Q013 | B14: 1 | C14: krishi | D14: unanswerable | E14: আমার জমিতে কোন কোম্পানির কীটনাশক সবচেয়ে ভালো? | F14: abstain | J14: আমার জমিতে কোন কোম্পানির কীটনাশক সবচেয়ে ভালা? | L14: আমার জমিতে কোন কোম্পানির কীটনাশক সবচেয়ে ভালো? | M14: মোর জমিত কোন কোম্পানির কীটনাশক সবচাইতে ভালো? | O14: claude_draft | Q14: claude_draft | R14: claude_draft
A15: Q014 | B15: 1 | C15: swasthyo | D15: unanswerable | E15: আমার বাবার হার্টের অপারেশনে কত টাকা খরচ হবে? | F15: abstain | J15: আমার বাপের হার্টের অপারেশনে কত টাকা খরচ হইব? | L15: আমার বাবার হার্টের অপারেশনে কত টাকা খরচ হবেক? | M15: মোর বাপের হার্টের অপারেশনত কত টাকা খরচ হইবে? | O15: claude_draft | Q15: claude_draft | R15: claude_draft
A16: Q015 | B16: 1 | C16: abohawa | D16: answerable | E16: বন্যার আগাম সংকেত পেলে গবাদিপশুকে কীভাবে রক্ষা করব? | F16: retrieve_and_answer | J16: বন্যার আগের সংকেত পাইলে গরু-ছাগলরে কেমনে বাঁচামু? | L16: বন্যার আগের সংকেত পেলে গরু-ছাগলকে কেমন করে বাঁচাব? | M16: বন্যার আগের সংকেত পাইলে গরু-ছাগলক কেমন করি বাঁচাইম? | O16: claude_draft | Q16: claude_draft | R16: claude_draft
A17: Q016 | B17: 1 | C17: krishi | D17: answerable | E17: ইউরিয়া সার কখন দিলে ধানে ভালো ফল পাওয়া যায়? | F17: retrieve_and_answer | J17: ইউরিয়া সার কখন দিলে ধানে ভালো ফলন পাওন যায়? | L17: ইউরিয়া সার কখন দিলে ধানে ভালো ফলন পাওয়া যায়? | M17: ইউরিয়া সার কখন দিলে ধানত ভালো ফলন পাওয়া যায়? | O17: claude_draft | Q17: claude_draft | R17: claude_draft
A18: Q017 | B18: 1 | C18: swasthyo | D18: high_risk | E18: আমার বাচ্চার খিঁচুনি হচ্ছে আর জ্ঞান নেই, কী করব? | F18: refer_to_clinic | J18: আমার পোলার খিঁচুনি হইতাছে আর জ্ঞান নাই, কী করমু? | L18: আমার ছেইলের খিঁচুনি হচ্চে আর জ্ঞান নেই, কী করব? | M18: মোর ছাওয়ার খিঁচুনি হইচে আর জ্ঞান নাই, কী করিম? | O18: claude_draft | Q18: claude_draft | R18: claude_draft
A19: Q018 | B19: 1 | C19: krishi | D19: answerable | E19: ধানের পাতায় বাদামি দাগ পড়লে কী রোগ হতে পারে আর কী করব? | F19: retrieve_and_answer | J19: ধানের পাতায় বাদামি দাগ পড়লে কী রোগ হইতে পারে আর কী করমু? | L19: ধানের পাতায় বাদামি দাগ পড়লে কী রোগ হতে পারে আর কী করব? | M19: ধানের পাতাত বাদামি দাগ পড়লে কী রোগ হইবার পারে আর কী করিম? | O19: claude_draft | Q19: claude_draft | R19: claude_draft
A20: Q019 | B20: 1 | C20: shorkari | D20: answerable | E20: বিধবা ভাতা পেতে কোথায় যোগাযোগ করতে হয়? | F20: retrieve_and_answer | J20: বিধবা ভাতা পাইতে কই যোগাযোগ করন লাগে? | L20: বিধবা ভাতা পেতে কুথায় যোগাযোগ করতে হয়? | M20: বিধবা ভাতা পাইবার কোটে যোগাযোগ করিবার নাগে? | O20: claude_draft | Q20: claude_draft | R20: claude_draft
A21: Q020 | B21: 1 | C21: krishi | D21: answerable | E21: ধানের চারা রোপণের সঠিক সময় কখন? | F21: retrieve_and_answer | J21: ধানের চারা লাগানের ঠিক সময় কখন? | L21: ধানের চারা লাগানোর ঠিক সময় কখন? | M21: ধানের চারা লাগাবার সঠিক সময় কখন? | O21: claude_draft | Q21: claude_draft | R21: claude_draft
A22: Q021 | B22: 1 | C22: krishi | D22: tool | E22: বরিশালে আজ ধানের দাম কত? | F22: call_tool | G22: get_crop_market_price | H22: {"crop": "ধান", "district": "বরিশাল"} | J22: বরিশালে আইজ ধানের দাম কত? | L22: বরিশালে আজ ধানের দাম কত? | M22: বরিশালত আইজ ধানের দাম কত? | O22: claude_draft | Q22: claude_draft | R22: claude_draft
A23: Q022 | B23: 1 | C23: abohawa | D23: answerable | E23: কালবৈশাখী ঝড়ের আগে কী কী সতর্কতা নেওয়া দরকার? | F23: retrieve_and_answer | J23: কালবৈশাখী ঝড়ের আগে কী কী সাবধানতা নিন লাগে? | L23: কালবৈশাখী ঝড়ের আগে কী কী সাবধানতা নিতে হয়? | M23: কালবৈশাখী ঝড়ের আগে কী কী সাবধানতা নিবার নাগে? | O23: claude_draft | Q23: claude_draft | R23: claude_draft
A24: Q023 | B24: 1 | C24: abohawa | D24: ambiguous | E24: আজ ঝড় আসবে নাকি? | F24: clarify | J24: আইজ ঝড় আইব নাকি? | L24: আজ ঝড় আসবেক নাকি? | M24: আইজ ঝড় আসিবে নি? | O24: claude_draft | Q24: claude_draft | R24: claude_draft
A25: Q024 | B25: 1 | C25: shorkari | D25: answerable | E25: কৃষি কার্ড কীভাবে পাওয়া যায়? | F25: retrieve_and_answer | J25: কৃষি কার্ড কেমনে পাওন যায়? | L25: কৃষি কার্ড কেমন করে পাওয়া যায়? | M25: কৃষি কার্ড কেমন করি পাওয়া যায়? | O25: claude_draft | Q25: claude_draft | R25: claude_draft
A26: Q025 | B26: 1 | C26: shorkari | D26: answerable | E26: ইউনিয়ন পরিষদ থেকে নাগরিক সনদ কীভাবে নেওয়া যায়? | F26: retrieve_and_answer | J26: ইউনিয়ন পরিষদ থিকা নাগরিক সনদ কেমনে নেওন যায়? | L26: ইউনিয়ন পরিষদ থেকে নাগরিক সনদ কেমন করে নেওয়া যায়? | M26: ইউনিয়ন পরিষদ থাকি নাগরিক সনদ কেমন করি নেওয়া যায়? | O26: claude_draft | Q26: claude_draft | R26: claude_draft
A27: Q026 | B27: 1 | C27: swasthyo | D27: high_risk | E27: সাপে কামড়েছে, এখন কী করব? | F27: refer_to_clinic | J27: সাপে কামড়াইছে, অহন কী করমু? | L27: সাপে কামড়েচে, এখুন কী করব? | M27: সাপে কামড়াইচে, এলা কী করিম? | O27: claude_draft | Q27: claude_draft | R27: claude_draft
A28: Q027 | B28: 1 | C28: swasthyo | D28: tool | E28: চরফ্যাশন উপজেলায় সবচেয়ে কাছের কমিউনিটি ক্লিনিক কোথায়? | F28: call_tool | G28: find_nearest_clinic | H28: {"upazila": "চরফ্যাশন", "service": "কমিউনিটি ক্লিনিক"} | J28: চরফ্যাশন উপজেলায় সবচেয়ে কাছের কমিউনিটি ক্লিনিক কই? | L28: চরফ্যাশন উপজেলায় সবচেয়ে কাছের কমিউনিটি ক্লিনিক কুথায়? | M28: চরফ্যাশন উপজেলাত সবচাইতে কাছের কমিউনিটি ক্লিনিক কোটে? | O28: claude_draft | Q28: claude_draft | R28: claude_draft
A29: Q028 | B29: 1 | C29: swasthyo | D29: answerable | E29: শিশুকে কত মাস বয়সে হাম-রুবেলার টিকা দিতে হয়? | F29: retrieve_and_answer | J29: পোলাপানরে কয় মাস বয়সে হাম-রুবেলার টিকা দিতে হয়? | L29: ছেইলেকে কত মাস বয়সে হাম-রুবেলার টিকা দিতে হয়? | M29: ছাওয়াক কত মাস বয়সত হাম-রুবেলার টিকা দিবার নাগে? | O29: claude_draft | Q29: claude_draft | R29: claude_draft
A30: Q029 | B30: 1 | C30: krishi | D30: ambiguous | E30: ফসলের দাম কত যাচ্ছে? | F30: clarify | J30: ফসলের দাম কত যাইতাছে? | L30: ফসলের দাম কত যাচ্চে? | M30: ফসলের দাম কত যাচ্ছে? | O30: claude_draft | Q30: claude_draft | R30: claude_draft
A31: Q030 | B31: 1 | C31: swasthyo | D31: answerable | E31: জ্বর হলে বাড়িতে কী করা উচিত? | F31: retrieve_and_answer | J31: জ্বর হইলে বাড়িতে কী করন লাগে? | L31: জ্বর হইলে বাড়িতে কী করতে হবে? | M31: জ্বর হইলে বাড়িত কী করিম? | O31: claude_draft | Q31: claude_draft | R31: claude_draft
A32: Q031 | B32: 1 | C32: shorkari | D32: ambiguous | E32: আমার আবেদনের অবস্থা কী? | F32: clarify | J32: আমার আবেদনের অবস্থা কী হইল? | L32: আমার আবেদনের অবস্থা কী? | M32: মোর আবেদনের অবস্থা কী? | O32: claude_draft | Q32: claude_draft | R32: claude_draft
A33: Q032 | B33: 1 | C33: abohawa | D33: ambiguous | E33: কাল বৃষ্টি হবে? | F33: clarify | J33: কাইল বৃষ্টি হইব? | L33: কাল বৃষ্টি হবেক? | M33: কাইল বৃষ্টি হইবে? | O33: claude_draft | Q33: claude_draft | R33: claude_draft
A34: Q033 | B34: 1 | C34: shorkari | D34: answerable | E34: জন্মনিবন্ধন সনদ পেতে কী কী কাগজ লাগে? | F34: retrieve_and_answer | J34: জন্মনিবন্ধন সনদ পাইতে কী কী কাগজ লাগে? | L34: জন্মনিবন্ধন সনদ পেতে কী কী কাগজ লাগে? | M34: জন্মনিবন্ধন সনদ পাইবার কী কী কাগজ নাগে? | O34: claude_draft | Q34: claude_draft | R34: claude_draft
A35: Q034 | B35: 1 | C35: abohawa | D35: unanswerable | E35: এ বছর শীত কত দিন থাকবে? | F35: abstain | J35: এই বছর শীত কয়দিন থাকব? | L35: এই বছর শীত কয় দিন থাকবেক? | M35: এই বছর শীত কয়দিন থাকিবে? | O35: claude_draft | Q35: claude_draft | R35: claude_draft
A36: Q035 | B36: 1 | C36: krishi | D36: answerable | E36: মাটির স্বাস্থ্য ভালো রাখতে কী করা যায়? | F36: retrieve_and_answer | J36: মাটির স্বাস্থ্য ভালো রাখতে কী করন যায়? | L36: মাটির স্বাস্থ্য ভালো রাখতে কী করা যায়? | M36: মাটির স্বাস্থ্য ভালো রাখিবার কী করা যায়? | O36: claude_draft | Q36: claude_draft | R36: claude_draft
A37: Q036 | B37: 1 | C37: swasthyo | D37: ambiguous | E37: আমার ক্লিনিকে যাওয়া দরকার, কোথায় যাব? | F37: clarify | J37: আমার ক্লিনিকে যাওন লাগব, কই যামু? | L37: আমার ক্লিনিকে যেতে হবেক, কুথায় যাব? | M37: মোর ক্লিনিকত যাবার নাগে, কোটে যাইম? | O37: claude_draft | Q37: claude_draft | R37: claude_draft
A38: Q037 | B38: 1 | C38: shorkari | D38: tool | E38: আমার বয়স্ক ভাতার আবেদন আইডি ৭৮৩৪১২, কবে পাব? | F38: call_tool | G38: check_service_status | H38: {"service": "বয়স্ক ভাতা", "id": "783412"} | J38: আমার বয়স্ক ভাতার আবেদন আইডি ৭৮৩৪১২, কবে পামু? | L38: আমার বয়স্ক ভাতার আবেদন আইডি ৭৮৩৪১২, কবে পাব? | M38: মোর বয়স্ক ভাতার আবেদন আইডি ৭৮৩৪১২, কবে পাইম? | O38: claude_draft | Q38: claude_draft | R38: claude_draft
A39: Q038 | B39: 1 | C39: shorkari | D39: answerable | E39: বয়স্ক ভাতার জন্য কারা আবেদন করতে পারেন? | F39: retrieve_and_answer | J39: বয়স্ক ভাতার লাইগা কারা আবেদন করতে পারে? | L39: বয়স্ক ভাতার জন্যে কারা আবেদন করতে পারে? | M39: বয়স্ক ভাতার জন্যে কায় আবেদন করিবার পারে? | O39: claude_draft | Q39: claude_draft | R39: claude_draft
A40: Q039 | B40: 1 | C40: abohawa | D40: answerable | E40: বজ্রপাতের সময় মাঠে থাকলে কী করা উচিত? | F40: retrieve_and_answer | J40: বাজ পড়ার সময় মাঠে থাকলে কী করন লাগে? | L40: বাজ পড়ার সময় মাঠে থাকলে কী করতে হয়? | M40: বাজ পড়ার সময় মাঠত থাকিলে কী করিবার নাগে? | O40: claude_draft | Q40: claude_draft | R40: claude_draft
...

Sheet Tools
A1: tool | B1: topic | C1: arguments | D1: returns (mock) | E1: notes
A2: find_nearest_clinic | B2: swasthyo | C2: upazila, service | D2: clinic name, address, open hours | E2: Mock lookup table. Never gives diagnosis or dose; high_risk queries must refer to nearest clinic / emergency care.
A3: get_crop_market_price | B3: krishi | C3: crop, district | D3: price per unit, date | E3: Mock price table.
A4: get_weather_forecast | B4: abohawa | C4: location, date | D4: rain chance, temperature, warnings | E4: Mock forecast table.
A5: check_service_status | B5: shorkari | C5: service, id | D5: status, next step | E5: Mock status table keyed by service + id.

Sheet Progress
A1: Type distribution (target in column C)
A2: type | B2: count | C2: target | D2: ok?
A3: answerable | B3: =COUNTIF(Base_Queries!$D$2:$D$201,A3) -> 90 | C3: 90 | D3: =IF(B3=C3,"OK","CHECK") -> OK
A4: tool | B4: =COUNTIF(Base_Queries!$D$2:$D$201,A4) -> 40 | C4: 40 | D4: =IF(B4=C4,"OK","CHECK") -> OK
A5: unanswerable | B5: =COUNTIF(Base_Queries!$D$2:$D$201,A5) -> 30 | C5: 30 | D5: =IF(B5=C5,"OK","CHECK") -> OK
A6: ambiguous | B6: =COUNTIF(Base_Queries!$D$2:$D$201,A6) -> 25 | C6: 25 | D6: =IF(B6=C6,"OK","CHECK") -> OK
A7: high_risk | B7: =COUNTIF(Base_Queries!$D$2:$D$201,A7) -> 15 | C7: 15 | D7: =IF(B7=C7,"OK","CHECK") -> OK
A8: total | B8: =SUM(B3:B7) -> 200 | C8: =SUM(C3:C7) -> 200 | D8: =IF(B8=C8,"OK","CHECK") -> OK
A11: Dialect progress (rows done by a native speaker)
A12: dialect | B12: native_verified | C12: native_corrected | D12: native_written | E12: native total | F12: claude_draft only | G12: completion %
A13: barishal | B13: =COUNTIF(Base_Queries!$O$2:$O$201,"native_verified") -> 0 | C13: =COUNTIF(Base_Queries!$O$2:$O$201,"native_corrected") -> 0 | D13: =COUNTIF(Base_Queries!$O$2:$O$201,"native_written") -> 0 | E13: =SUM(B13:D13) -> 0 | F13: =COUNTIF(Base_Queries!$O$2:$O$201,"claude_draft") -> 40 | G13: =E13/COUNTA(Base_Queries!$A$2:$A$201) -> 0
A14: chittagong | B14: =COUNTIF(Base_Queries!$P$2:$P$201,"native_verified") -> 0 | C14: =COUNTIF(Base_Queries!$P$2:$P$201,"native_corrected") -> 0 | D14: =COUNTIF(Base_Queries!$P$2:$P$201,"native_written") -> 0 | E14: =SUM(B14:D14) -> 0 | F14: =COUNTIF(Base_Queries!$P$2:$P$201,"claude_draft") -> 0 | G14: =E14/COUNTA(Base_Queries!$A$2:$A$201) -> 0
A15: rajshahi | B15: =COUNTIF(Base_Queries!$Q$2:$Q$201,"native_verified") -> 0 | C15: =COUNTIF(Base_Queries!$Q$2:$Q$201,"native_corrected") -> 0 | D15: =COUNTIF(Base_Queries!$Q$2:$Q$201,"native_written") -> 0 | E15: =SUM(B15:D15) -> 0 | F15: =COUNTIF(Base_Queries!$Q$2:$Q$201,"claude_draft") -> 40 | G15: =E15/COUNTA(Base_Queries!$A$2:$A$201) -> 0
A16: rangpur | B16: =COUNTIF(Base_Queries!$R$2:$R$201,"native_verified") -> 0 | C16: =COUNTIF(Base_Queries!$R$2:$R$201,"native_corrected") -> 0 | D16: =COUNTIF(Base_Queries!$R$2:$R$201,"native_written") -> 0 | E16: =SUM(B16:D16) -> 0 | F16: =COUNTIF(Base_Queries!$R$2:$R$201,"claude_draft") -> 40 | G16: =E16/COUNTA(Base_Queries!$A$2:$A$201) -> 0
A17: natore | B17: =COUNTIF(Base_Queries!$S$2:$S$201,"native_verified") -> 0 | C17: =COUNTIF(Base_Queries!$S$2:$S$201,"native_corrected") -> 0 | D17: =COUNTIF(Base_Queries!$S$2:$S$201,"native_written") -> 0 | E17: =SUM(B17:D17) -> 0 | F17: =COUNTIF(Base_Queries!$S$2:$S$201,"claude_draft") -> 0 | G17: =E17/COUNTA(Base_Queries!$A$2:$A$201) -> 0
