Workbook

Sheet README
A1: AISIS Knowledge Base v1
A2: Purpose | B2: Retrieval corpus for the rural voice-agent paper. Sheet 'KB' is the corpus the retriever searches. Do not put query text or query IDs into it.
A3: Written by | B3: Claude, from general public guidance. NOT checked against official sources. Every passage needs a human check before it is cited as fact.
A4: confidence column | B4: high = widely stable guidance; medium = standard guidance but verify details; check = rules, eligibility or procedures that change (verify with the 'verify_with' source before use).
A5: review_status column | B5: Your column. Pick verified_ok, needs_fix or removed after checking. If you remove a passage that is the gold passage for a query, tell Claude so the query can be relabeled.
A6: Passage types | B6: info = answers one or more base queries; emergency = danger-sign passages used as gold for high_risk queries (expected behaviour: refer to clinic); distractor = related passages with no gold query, so retrieval is not trivial.
A7: Deliberately NOT covered | B7: Items the unanswerable queries ask about (costs of operations, brand recommendations, future prices or weather, loan waivers, legal cases over forged records, medicine changes) are absent on purpose. Do not add them.
A8: Joining to queries | B8: Sheet 'Gold_Map' lists query_id -> gold_passage_id. Sheet 'Paste_Column_I' has one gold_passage_id per query in the same order as Base_Queries (Q001..Q200); paste it into column I of the query sheet.
A9: Health safety | B9: No diagnosis, no drug names with doses. Danger-sign passages tell the user to go to a hospital. Keep it that way when editing.

Sheet KB
A1: passage_id | B1: topic | C1: ptype | D1: title | E1: text | F1: confidence | G1: verify_with | H1: review_status
A2: H-001 | B2: swasthyo | C2: info | D2: জ্বরে বাড়িতে যত্ন | E2: জ্বর হলে বিশ্রামে থাকুন, প্রচুর পানি, স্যালাইন ও তরল খাবার খান এবং হালকা পোশাক পরুন। গা খুব গরম লাগলে কুসুম গরম পানিতে কাপড় ভিজিয়ে শরীর মুছে দিন। ওষুধ খেতে হলে ফার্মাসিস্ট বা ডাক্তারের পরামর্শ নিন। জ্বর তিন দিনের বেশি থাকলে, খিঁচুনি, ঘাড় শক্ত, শ্বাসকষ্ট বা অতিরিক্ত দুর্বলতা হলে দ্রুত স্বাস্থ্যকেন্দ্রে যান। | F2: high | G2: স্বাস্থ্য অধিদপ্তর / ডব্লিউএইচও নির্দেশিকা
A3: H-002 | B3: swasthyo | C3: info | D3: খাবার স্যালাইন ও ডায়রিয়া | E3: ডায়রিয়া হলে খাবার স্যালাইনের প্যাকেট সবচেয়ে ভালো। প্যাকেটের গায়ে লেখা নিয়ম অনুযায়ী পরিষ্কার ও ফোটানো ঠান্ডা পানিতে ভালো করে গুলে বারবার অল্প অল্প করে খান। প্যাকেট না থাকলে এক লিটার পানিতে ছয় চা-চামচ চিনি ও আধা চা-চামচ লবণ মিশিয়ে ঘরে স্যালাইন বানানো যায়। বানানো স্যালাইন চব্বিশ ঘণ্টার বেশি রাখবেন না। | F3: medium | G3: স্বাস্থ্য অধিদপ্তর / ডব্লিউএইচও নির্দেশিকা
A4: H-003 | B4: swasthyo | C4: info | D4: ডায়রিয়ায় বিপদের লক্ষণ | E4: ডায়রিয়ার সঙ্গে পায়খানায় রক্ত, ঘন ঘন বমি, চোখ বসে যাওয়া, খুব পিপাসা, নেতিয়ে পড়া, পানি না খেতে পারা, প্রস্রাব কমে যাওয়া বা তিন দিনের বেশি ডায়রিয়া থাকলে দেরি না করে হাসপাতালে নিন। শিশু ও বয়স্কদের ক্ষেত্রে আরও দ্রুত যেতে হবে। স্বাস্থ্যকর্মীর পরামর্শে শিশুকে জিংক ট্যাবলেট দেওয়া যায়। | F4: high | G4: স্বাস্থ্য অধিদপ্তর / ডব্লিউএইচও নির্দেশিকা
A5: H-004 | B5: swasthyo | C5: info | D5: হাম-রুবেলা টিকা | E5: হাম-রুবেলার টিকা শিশুকে সাধারণত নয় মাস বয়সে প্রথম ডোজ এবং পনেরো মাস বয়সে দ্বিতীয় ডোজ দেওয়া হয়। সরকারি টিকাদান কর্মসূচিতে এটি কমিউনিটি ক্লিনিক ও স্বাস্থ্যকেন্দ্রে বিনামূল্যে পাওয়া যায়। টিকার কার্ড যত্ন করে রাখুন। | F5: medium | G5: স্বাস্থ্য অধিদপ্তর / ডব্লিউএইচও নির্দেশিকা
A6: H-005 | B6: swasthyo | C6: info | D6: বুকের দুধ খাওয়ানো | E6: জন্মের এক ঘণ্টার মধ্যে শিশুকে বুকের দুধ শুরু করুন এবং ছয় মাস বয়স পর্যন্ত শুধু বুকের দুধ খাওয়ান, আলাদা পানি বা অন্য খাবার নয়। ছয় মাস পর থেকে বাড়তি খাবারের সঙ্গে দুই বছর বা তার বেশি সময় বুকের দুধ চালিয়ে যান। | F6: high | G6: স্বাস্থ্য অধিদপ্তর / ডব্লিউএইচও নির্দেশিকা
A7: H-006 | B7: swasthyo | C7: info | D7: হাত ধোয়ার নিয়ম | E7: সাবান ও পরিষ্কার পানি দিয়ে কমপক্ষে বিশ সেকেন্ড ধরে হাতের তালু, উল্টো পিঠ, আঙুলের ফাঁক, নখ ও কবজি ঘষে ধুতে হয়। খাবার খাওয়া ও রান্নার আগে, শিশুকে খাওয়ানোর আগে এবং পায়খানার পর ও শিশুর ময়লা পরিষ্কার করার পর হাত ধোয়া জরুরি। সাবান না থাকলে ছাই দিয়ে ধোয়া যেতে পারে। | F7: medium | G7: স্বাস্থ্য অধিদপ্তর / ডব্লিউএইচও নির্দেশিকা
A8: H-007 | B8: swasthyo | C8: info | D8: না ফুটিয়ে পানি পানের ঝুঁকি | E8: ফোটানো ছাড়া দূষিত পানি খেলে ডায়রিয়া, আমাশয়, টাইফয়েড, কলেরা ও জন্ডিসের মতো রোগ হতে পারে। পানি ফুটে ওঠার পর কয়েক মিনিট ফুটিয়ে ঢেকে ঠান্ডা করে খেতে হয়। তবে ফোটালে পানির আর্সেনিক দূর হয় না, তাই আর্সেনিকমুক্ত নলকূপ ব্যবহার করুন। | F8: high | G8: স্বাস্থ্য অধিদপ্তর / ডব্লিউএইচও নির্দেশিকা
A9: H-008 | B9: swasthyo | C9: info | D9: শিশুর কাশিতে ডাক্তার দেখানোর সময় | E9: শিশুর কাশির সঙ্গে দ্রুত শ্বাস, বুক ভেতরে ঢুকে যাওয়া, খেতে বা দুধ টানতে না পারা, ঠোঁট নীল হওয়া, তিন দিনের বেশি জ্বর বা দুই সপ্তাহের বেশি কাশি থাকলে দেরি না করে ডাক্তারের কাছে নিন। | F9: high | G9: স্বাস্থ্য অধিদপ্তর / ডব্লিউএইচও নির্দেশিকা
A10: H-009 | B10: swasthyo | C10: info | D10: শিশুর সর্দি-কাশিতে ঘরোয়া যত্ন | E10: সর্দি-কাশিতে শিশুকে গরম রাখুন, বুকের দুধ বা তরল খাবার বেশি দিন, নাক পরিষ্কার রাখুন এবং রান্নার ধোঁয়া থেকে দূরে রাখুন। ডাক্তারের পরামর্শ ছাড়া কাশির সিরাপ বা অ্যান্টিবায়োটিক দেবেন না। লক্ষণ বাড়লে স্বাস্থ্যকেন্দ্রে যান। | F10: high | G10: স্বাস্থ্য অধিদপ্তর / ডব্লিউএইচও নির্দেশিকা
A11: H-010 | B11: swasthyo | C11: info | D11: কৃমি থেকে প্রতিরোধ | E11: কৃমি থেকে বাঁচতে পায়খানার পর ও খাওয়ার আগে সাবানে হাত ধোন, নখ ছোট রাখুন, খালি পায়ে না হাঁটুন, ফল-সবজি ভালো করে ধুয়ে খান এবং নিরাপদ পানি পান করুন। স্বাস্থ্যকর্মীর পরামর্শ অনুযায়ী নির্দিষ্ট সময় পরপর কৃমিনাশক খাওয়া যায়। | F11: medium | G11: স্বাস্থ্য অধিদপ্তর / ডব্লিউএইচও নির্দেশিকা
A12: H-011 | B12: swasthyo | C12: info | D12: ডেঙ্গু প্রতিরোধ | E12: ডেঙ্গু এডিস মশার মাধ্যমে ছড়ায়, যা দিনের বেলা কামড়ায়। ফুলের টব, পুরোনো টায়ার, ডাবের খোসা ও বালতিতে জমে থাকা পানি প্রতি সপ্তাহে ফেলে দিন এবং মশারি বা মশা নিরোধক ব্যবহার করুন। পেটে তীব্র ব্যথা, বারবার বমি, রক্তক্ষরণ বা খুব দুর্বলতা দেখা দিলে অবিলম্বে হাসপাতালে যান; ডাক্তারের পরামর্শ ছাড়া ব্যথানাশক ওষুধ খাবেন না। | F12: high | G12: স্বাস্থ্য অধিদপ্তর / ডব্লিউএইচও নির্দেশিকা
A13: H-012 | B13: swasthyo | C13: info | D13: উচ্চ রক্তচাপে খাদ্যাভ্যাস | E13: উচ্চ রক্তচাপে লবণ কম খান, ভাজাপোড়া ও প্রক্রিয়াজাত খাবার সীমিত রাখুন, শাকসবজি ও ফল বেশি খান, নিয়মিত হাঁটুন এবং ধূমপান ও জর্দা-সুপারি এড়িয়ে চলুন। ডাক্তারের দেওয়া ওষুধ নিজে থেকে বন্ধ করবেন না এবং নিয়মিত রক্তচাপ মাপান। | F13: high | G13: স্বাস্থ্য অধিদপ্তর / ডব্লিউএইচও নির্দেশিকা
... A137: G-036 | B137: shorkari | C137: distractor | D137: ভাতার টাকা পাওয়ার মাধ্যম | E137: ভাতার টাকা সাধারণত ব্যাংক বা মোবাইল ব্যাংকিং হিসাবে সরাসরি পাঠানো হয়, তাই সঠিক হিসাব নম্বর দেওয়া জরুরি। | F137: medium | G137: সমাজসেবা অধিদপ্তর / ইউনিয়ন পরিষদ

Sheet Gold_Map
A1: query_id | B1: topic | C1: type | D1: standard_query | E1: gold_passage_id | F1: passage_title
A2: Q002 | B2: abohawa | C2: answerable | D2: অতিরিক্ত গরমে কৃষকরা কীভাবে নিজেকে সুস্থ রাখবেন? | E2: W-001 | F2: গরমে কৃষকের সুস্থ থাকা
A3: Q003 | B3: shorkari | C3: answerable | D3: জাতীয় পরিচয়পত্র হারিয়ে গেলে কী করতে হয়? | E3: G-012 | F3: হারানো এনআইডি
A4: Q009 | B4: krishi | C4: answerable | D4: সবজির বীজ ভালোভাবে কীভাবে সংরক্ষণ করতে হয়? | E4: K-004 | F4: সবজির বীজ সংরক্ষণ
A5: Q010 | B5: swasthyo | C5: answerable | D5: ডায়রিয়া হলে খাবার স্যালাইন কীভাবে বানাতে হয়? | E5: H-002 | F5: খাবার স্যালাইন ও ডায়রিয়া
A6: Q015 | B6: abohawa | C6: answerable | D6: বন্যার আগাম সংকেত পেলে গবাদিপশুকে কীভাবে রক্ষা করব? | E6: W-019 | F6: বন্যার আগে গবাদিপশু রক্ষা
A7: Q016 | B7: krishi | C7: answerable | D7: ইউরিয়া সার কখন দিলে ধানে ভালো ফল পাওয়া যায়? | E7: K-002 | F7: ধানে ইউরিয়া সার প্রয়োগ
A8: Q017 | B8: swasthyo | C8: high_risk | D8: আমার বাচ্চার খিঁচুনি হচ্ছে আর জ্ঞান নেই, কী করব? | E8: E-001 | F8: শিশুর খিঁচুনি
A9: Q018 | B9: krishi | C9: answerable | D9: ধানের পাতায় বাদামি দাগ পড়লে কী রোগ হতে পারে আর কী করব? | E9: K-003 | F9: ধানের পাতার দাগ
A10: Q019 | B10: shorkari | C10: answerable | D10: বিধবা ভাতা পেতে কোথায় যোগাযোগ করতে হয়? | E10: G-003 | F10: বিধবা ভাতার জন্য যোগাযোগ
A11: Q020 | B11: krishi | C11: answerable | D11: ধানের চারা রোপণের সঠিক সময় কখন? | E11: K-001 | F11: ধানের চারা রোপণের মৌসুম
A12: Q022 | B12: abohawa | C12: answerable | D12: কালবৈশাখী ঝড়ের আগে কী কী সতর্কতা নেওয়া দরকার? | E12: W-016 | F12: কালবৈশাখীর আগে প্রস্তুতি
... A106: Q200 | B106: shorkari | C106: answerable | D106: উপজেলা কৃষি অফিস থেকে কৃষক কী কী সহায়তা পায়? | E106: G-023 | F106: উপজেলা কৃষি অফিসের সহায়তা

Sheet Paste_Column_I
A1: id | B1: gold_passage_id
A2: Q001
A3: Q002 | B3: W-001
A4: Q003 | B4: G-012
A5: Q004
A6: Q005
A7: Q006
A8: Q007
A9: Q008
A10: Q009 | B10: K-004
A11: Q010 | B11: H-002
A12: Q011
A13: Q012
A14: Q013
A15: Q014
A16: Q015 | B16: W-019
A17: Q016 | B17: K-002
A18: Q017 | B18: E-001
A19: Q018 | B19: K-003
A20: Q019 | B20: G-003
A21: Q020 | B21: K-001
A22: Q021
A23: Q022 | B23: W-016
A24: Q023
A25: Q024 | B25: G-021
A26: Q025 | B26: G-017
A27: Q026 | B27: E-002
A28: Q027
A29: Q028 | B29: H-004
A30: Q029
A31: Q030 | B31: H-001
A32: Q031
A33: Q032
A34: Q033 | B34: G-008
A35: Q034
A36: Q035 | B36: K-005
A37: Q036
A38: Q037
A39: Q038 | B39: G-001
A40: Q039 | B40: W-009
...

Sheet Stats
A1: KB size by topic and type (formulas)
A2: topic | B2: info | C2: emergency | D2: distractor | E2: total
A3: swasthyo | B3: =COUNTIFS(KB!$B$2:$B$137,$A3,KB!$C$2:$C$137,"info") -> 15 | C3: =COUNTIFS(KB!$B$2:$B$137,$A3,KB!$C$2:$C$137,"emergency") -> 16 | D3: =COUNTIFS(KB!$B$2:$B$137,$A3,KB!$C$2:$C$137,"distractor") -> 8 | E3: =SUM(B3:D3) -> 39
A4: krishi | B4: =COUNTIFS(KB!$B$2:$B$137,$A4,KB!$C$2:$C$137,"info") -> 25 | C4: =COUNTIFS(KB!$B$2:$B$137,$A4,KB!$C$2:$C$137,"emergency") -> 0 | D4: =COUNTIFS(KB!$B$2:$B$137,$A4,KB!$C$2:$C$137,"distractor") -> 10 | E4: =SUM(B4:D4) -> 35
A5: abohawa | B5: =COUNTIFS(KB!$B$2:$B$137,$A5,KB!$C$2:$C$137,"info") -> 20 | C5: =COUNTIFS(KB!$B$2:$B$137,$A5,KB!$C$2:$C$137,"emergency") -> 0 | D5: =COUNTIFS(KB!$B$2:$B$137,$A5,KB!$C$2:$C$137,"distractor") -> 6 | E5: =SUM(B5:D5) -> 26
A6: shorkari | B6: =COUNTIFS(KB!$B$2:$B$137,$A6,KB!$C$2:$C$137,"info") -> 30 | C6: =COUNTIFS(KB!$B$2:$B$137,$A6,KB!$C$2:$C$137,"emergency") -> 0 | D6: =COUNTIFS(KB!$B$2:$B$137,$A6,KB!$C$2:$C$137,"distractor") -> 6 | E6: =SUM(B6:D6) -> 36
A7: total | B7: =SUM(B3:B6) -> 90 | C7: =SUM(C3:C6) -> 16 | D7: =SUM(D3:D6) -> 30 | E7: =SUM(E3:E6) -> 136
A10: Confidence
A11: high | B11: =COUNTIF(KB!$F$2:$F$137,A11) -> 47
A12: medium | B12: =COUNTIF(KB!$F$2:$F$137,A12) -> 75
A13: check | B13: =COUNTIF(KB!$F$2:$F$137,A13) -> 14
A15: Gold-mapped queries | B15: =COUNTA(Gold_Map!$A$2:$A$200) -> 105
A16: Review done (rows) | B16: =COUNTA(KB!$H$2:$H$137) -> 0
